{
    "registryname": "chemical_caster",
    "localizedname": "Chemical Caster",
    "requires-blueprint": true,
    "color": "3D3D3D",
    "parts": [
        {
            "x": -2,
            "y": 0,
            "z": 2,
            "elements": [
                "modularmachinery:blockoutputbus@3",
                "modularmachinery:blockoutputbus@4",
                "modularmachinery:blockoutputbus@5",
                "modularmachinery:blockoutputbus@6"
            ]
        },
        {
            "x": -1,
            "y": 2,
            "z": 3,
            "elements": [
                "contenttweaker:reinforced_glass_casing@0"
            ]
        },
        {
            "x": 1,
            "y": 2,
            "z": 1,
            "elements": [
                "contenttweaker:reinforced_glass_casing@0"
            ]
        },
        {
            "x": 0,
            "y": 4,
            "z": 4,
            "elements": [
                "modulardiversity:blockmekheatinput@0"
            ]
        },
        {
            "x": 2,
            "y": 4,
            "z": 2,
            "elements": [
                "modulardiversity:blockmekheatinput@0"
            ]
        },
        {
            "x": -1,
            "y": 0,
            "z": 2,
            "nbt": {"Items":[{"Slot":"0b","id":"tconstruct:cast_custom","Count":"1b","Damage":"0s"}]},
            "elements": [
                "tconstruct:casting@0"
            ]
        },
        {
            "x": 0,
            "y": 2,
            "z": 3,
            "elements": [
                "tconstruct:faucet@2",
                "tconstruct:faucet@3",
                "tconstruct:faucet@4",
                "tconstruct:faucet@5"
            ]
        },
        {
            "x": 0,
            "y": 0,
            "z": 2,
            "elements": [
                "tconstruct:casting@1"
            ]
        },
        {
            "x": 1,
            "y": 2,
            "z": 3,
            "elements": [
                "contenttweaker:reinforced_glass_casing@0"
            ]
        },
        {
            "x": 1,
            "y": 0,
            "z": 2,
            "nbt": {"Items":[{"Slot":"0b","id":"tconstruct:cast_custom","Count":"1b","Damage":"0s"}]},
            "elements": [
                "tconstruct:casting@0"
            ]
        },
        {
            "x": 0,
            "y": 0,
            "z": 4,
            "elements": [
                "modularmachinery:blockenergyinputhatch@6",
                "modularmachinery:blockenergyinputhatch@7"
            ]
        },
        {
            "x": 2,
            "y": 0,
            "z": 2,
            "elements": [
                "modularmachinery:blockinputbus@3",
                "modularmachinery:blockinputbus@4",
                "modularmachinery:blockinputbus@5",
                "modularmachinery:blockinputbus@6"
            ]
        },
        {
            "x": -1,
            "y": 5,
            "z": 2,
            "elements": [
                "modularmachinery:blockcasing@4"
            ]
        },
        {
            "x": -1,
            "y": 3,
            "z": 1,
            "elements": [
                "contenttweaker:reinforced_glass_casing@0"
            ]
        },
        {
            "x": 0,
            "y": 5,
            "z": 2,
            "elements": [
                "alchemistry:chemical_dissolver@0"
            ]
        },
        {
            "x": 0,
            "y": 3,
            "z": 1,
            "elements": [
                "tconstruct:faucet@2",
                "tconstruct:faucet@3",
                "tconstruct:faucet@4",
                "tconstruct:faucet@5"
            ]
        },
        {
            "x": 1,
            "y": 5,
            "z": 2,
            "elements": [
                "modularmachinery:blockcasing@4"
            ]
        },
        {
            "x": -2,
            "y": 1,
            "z": 2,
            "elements": [
                "tconstruct:smeltery_io@0",
                "tconstruct:smeltery_io@4",
                "tconstruct:smeltery_io@8",
                "tconstruct:smeltery_io@12"
            ]
        },
        {
            "x": 0,
            "y": 1,
            "z": 0,
            "elements": [
                "tconstruct:smeltery_io@0",
                "tconstruct:smeltery_io@4",
                "tconstruct:smeltery_io@8",
                "tconstruct:smeltery_io@12"
            ]
        },
        {
            "x": -1,
            "y": 3,
            "z": 3,
            "elements": [
                "contenttweaker:reinforced_glass_casing@0"
            ]
        },
        {
            "x": 1,
            "y": 3,
            "z": 1,
            "elements": [
                "contenttweaker:reinforced_glass_casing@0"
            ]
        },
        {
            "x": -1,
            "y": 1,
            "z": 2,
            "elements": [
                "tconstruct:faucet@2",
                "tconstruct:faucet@3",
                "tconstruct:faucet@4",
                "tconstruct:faucet@5"
            ]
        },
        {
            "x": 0,
            "y": 3,
            "z": 3,
            "elements": [
                "tconstruct:faucet@2",
                "tconstruct:faucet@3",
                "tconstruct:faucet@4",
                "tconstruct:faucet@5"
            ]
        },
        {
            "x": 0,
            "y": 1,
            "z": 2,
            "elements": [
                "contenttweaker:crystal_core@0"
            ]
        },
        {
            "x": 1,
            "y": 3,
            "z": 3,
            "elements": [
                "contenttweaker:reinforced_glass_casing@0"
            ]
        },
        {
            "x": 1,
            "y": 1,
            "z": 2,
            "elements": [
                "tconstruct:faucet@2",
                "tconstruct:faucet@3",
                "tconstruct:faucet@4",
                "tconstruct:faucet@5"
            ]
        },
        {
            "x": 0,
            "y": 1,
            "z": 4,
            "elements": [
                "tconstruct:smeltery_io@0",
                "tconstruct:smeltery_io@4",
                "tconstruct:smeltery_io@8",
                "tconstruct:smeltery_io@12"
            ]
        },
        {
            "x": 2,
            "y": 1,
            "z": 2,
            "elements": [
                "tconstruct:smeltery_io@0",
                "tconstruct:smeltery_io@4",
                "tconstruct:smeltery_io@8",
                "tconstruct:smeltery_io@12"
            ]
        },
        {
            "x": -1,
            "y": 4,
            "z": 1,
            "elements": [
                "contenttweaker:reinforced_glass_casing@0"
            ]
        },
        {
            "x": 0,
            "y": 6,
            "z": 2,
            "elements": [
                "modularmachinery:blockcasing@4"
            ]
        },
        {
            "x": -2,
            "y": 2,
            "z": 2,
            "elements": [
                "tconstruct:smeltery_io@0",
                "tconstruct:smeltery_io@4",
                "tconstruct:smeltery_io@8",
                "tconstruct:smeltery_io@12"
            ]
        },
        {
            "x": 0,
            "y": 2,
            "z": 0,
            "elements": [
                "tconstruct:smeltery_io@0",
                "tconstruct:smeltery_io@4",
                "tconstruct:smeltery_io@8",
                "tconstruct:smeltery_io@12"
            ]
        },
        {
            "x": -1,
            "y": 4,
            "z": 3,
            "elements": [
                "contenttweaker:reinforced_glass_casing@0"
            ]
        },
        {
            "x": 1,
            "y": 4,
            "z": 1,
            "elements": [
                "contenttweaker:reinforced_glass_casing@0"
            ]
        },
        {
            "x": -1,
            "y": 2,
            "z": 2,
            "elements": [
                "tconstruct:faucet@2",
                "tconstruct:faucet@3",
                "tconstruct:faucet@4",
                "tconstruct:faucet@5"
            ]
        },
        {
            "x": -1,
            "y": 0,
            "z": 1,
            "elements": [
                "modularmachinery:blockcasing@4"
            ]
        },
        {
            "x": 0,
            "y": 2,
            "z": 2,
            "elements": [
                "draconicevolution:draconic_block@0"
            ]
        },
        {
            "x": 1,
            "y": 4,
            "z": 3,
            "elements": [
                "contenttweaker:reinforced_glass_casing@0"
            ]
        },
        {
            "x": 0,
            "y": 0,
            "z": 1,
            "nbt": {"Items":[{"Slot":"0b","id":"tconstruct:cast_custom","Count":"1b","Damage":"0s"}]},
            "elements": [
                "tconstruct:casting@0"
            ]
        },
        {
            "x": 1,
            "y": 2,
            "z": 2,
            "elements": [
                "tconstruct:faucet@2",
                "tconstruct:faucet@3",
                "tconstruct:faucet@4",
                "tconstruct:faucet@5"
            ]
        },
        {
            "x": -1,
            "y": 0,
            "z": 3,
            "elements": [
                "modularmachinery:blockcasing@4"
            ]
        },
        {
            "x": 1,
            "y": 0,
            "z": 1,
            "elements": [
                "modularmachinery:blockcasing@4"
            ]
        },
        {
            "x": 0,
            "y": 2,
            "z": 4,
            "elements": [
                "tconstruct:smeltery_io@0",
                "tconstruct:smeltery_io@4",
                "tconstruct:smeltery_io@8",
                "tconstruct:smeltery_io@12"
            ]
        },
        {
            "x": 2,
            "y": 2,
            "z": 2,
            "elements": [
                "tconstruct:smeltery_io@0",
                "tconstruct:smeltery_io@4",
                "tconstruct:smeltery_io@8",
                "tconstruct:smeltery_io@12"
            ]
        },
        {
            "x": 0,
            "y": 0,
            "z": 3,
            "nbt": {"Items":[{"Slot":"0b","id":"tconstruct:cast_custom","Count":"1b","Damage":"0s"}]},
            "elements": [
                "tconstruct:casting@0"
            ]
        },
        {
            "x": 1,
            "y": 0,
            "z": 3,
            "elements": [
                "modularmachinery:blockcasing@4"
            ]
        },
        {
            "x": 0,
            "y": 5,
            "z": 1,
            "elements": [
                "modularmachinery:blockcasing@4"
            ]
        },
        {
            "x": -2,
            "y": 3,
            "z": 2,
            "elements": [
                "tconstruct:smeltery_io@0",
                "tconstruct:smeltery_io@4",
                "tconstruct:smeltery_io@8",
                "tconstruct:smeltery_io@12"
            ]
        },
        {
            "x": 0,
            "y": 3,
            "z": 0,
            "elements": [
                "tconstruct:smeltery_io@0",
                "tconstruct:smeltery_io@4",
                "tconstruct:smeltery_io@8",
                "tconstruct:smeltery_io@12"
            ]
        },
        {
            "x": -1,
            "y": 3,
            "z": 2,
            "elements": [
                "tconstruct:faucet@2",
                "tconstruct:faucet@3",
                "tconstruct:faucet@4",
                "tconstruct:faucet@5"
            ]
        },
        {
            "x": 0,
            "y": 5,
            "z": 3,
            "elements": [
                "modularmachinery:blockcasing@4"
            ]
        },
        {
            "x": -1,
            "y": 1,
            "z": 1,
            "elements": [
                "contenttweaker:reinforced_glass_casing@0"
            ]
        },
        {
            "x": 0,
            "y": 3,
            "z": 2,
            "elements": [
                "contenttweaker:crystal_core@0"
            ]
        },
        {
            "x": 0,
            "y": 1,
            "z": 1,
            "elements": [
                "tconstruct:faucet@2",
                "tconstruct:faucet@3",
                "tconstruct:faucet@4",
                "tconstruct:faucet@5"
            ]
        },
        {
            "x": 1,
            "y": 3,
            "z": 2,
            "elements": [
                "tconstruct:faucet@2",
                "tconstruct:faucet@3",
                "tconstruct:faucet@4",
                "tconstruct:faucet@5"
            ]
        },
        {
            "x": -1,
            "y": 1,
            "z": 3,
            "elements": [
                "contenttweaker:reinforced_glass_casing@0"
            ]
        },
        {
            "x": 1,
            "y": 1,
            "z": 1,
            "elements": [
                "contenttweaker:reinforced_glass_casing@0"
            ]
        },
        {
            "x": 0,
            "y": 3,
            "z": 4,
            "elements": [
                "tconstruct:smeltery_io@0",
                "tconstruct:smeltery_io@4",
                "tconstruct:smeltery_io@8",
                "tconstruct:smeltery_io@12"
            ]
        },
        {
            "x": 2,
            "y": 3,
            "z": 2,
            "elements": [
                "tconstruct:smeltery_io@0",
                "tconstruct:smeltery_io@4",
                "tconstruct:smeltery_io@8",
                "tconstruct:smeltery_io@12"
            ]
        },
        {
            "x": 0,
            "y": 1,
            "z": 3,
            "elements": [
                "tconstruct:faucet@2",
                "tconstruct:faucet@3",
                "tconstruct:faucet@4",
                "tconstruct:faucet@5"
            ]
        },
        {
            "x": 1,
            "y": 1,
            "z": 3,
            "elements": [
                "contenttweaker:reinforced_glass_casing@0"
            ]
        },
        {
            "x": -2,
            "y": 4,
            "z": 2,
            "elements": [
                "modulardiversity:blockmekheatinput@0"
            ]
        },
        {
            "x": 0,
            "y": 4,
            "z": 0,
            "elements": [
                "modulardiversity:blockmekheatinput@0"
            ]
        },
        {
            "x": -1,
            "y": 2,
            "z": 1,
            "elements": [
                "contenttweaker:reinforced_glass_casing@0"
            ]
        },
        {
            "x": 0,
            "y": 4,
            "z": 2,
            "elements": [
                "alchemistry:chemical_dissolver@0"
            ]
        },
        {
            "x": 0,
            "y": 2,
            "z": 1,
            "elements": [
                "tconstruct:faucet@2",
                "tconstruct:faucet@3",
                "tconstruct:faucet@4",
                "tconstruct:faucet@5"
            ]
        }
    ]}