{
    "registryname": "laser_focus",
    "localizedname": "Laser Focus",
    "requires-blueprint": true,
    "color": "4779A1",
    "parts": [
        {
            "x": -1,
            "y": 0,
            "z": 0,
            "elements": [
                "modularmachinery:blockoutputbus@0",
                "modularmachinery:blockoutputbus@1",
                "modularmachinery:blockoutputbus@2",
                "modularmachinery:blockoutputbus@3",
                "modularmachinery:blockoutputbus@4",
                "modularmachinery:blockoutputbus@5",
                "modularmachinery:blockoutputbus@6"
            ]
        },
        {
            "x": 1,
            "y": 0,
            "z": 0,
            "elements": [
                "modularmachinery:blockinputbus@0",
                "modularmachinery:blockinputbus@1",
                "modularmachinery:blockinputbus@2",
                "modularmachinery:blockinputbus@3",
                "modularmachinery:blockinputbus@4",
                "modularmachinery:blockinputbus@5",
                "modularmachinery:blockinputbus@6"
            ]
        },
        {
            "x": -2,
            "y": 0,
            "z": 0,
            "elements": [
                "modularmachinery:blockcasing@4"
            ]
        },
        {
            "x": -1,
            "y": 4,
            "z": 6,
            "elements": [
                "modularmachinery:blockcasing@4"
            ]
        },
        {
            "x": 2,
            "y": 0,
            "z": 0,
            "elements": [
                "modularmachinery:blockcasing@4"
            ]
        },
        {
            "x": 0,
            "y": 4,
            "z": 6,
            "elements": [
                "contenttweaker:portion_of_the_sun@0"
            ]
        },
        {
            "x": 1,
            "y": 4,
            "z": 6,
            "elements": [
                "modularmachinery:blockcasing@4"
            ]
        },
        {
            "x": -1,
            "y": 0,
            "z": 8,
            "elements": [
                "thaumicaugmentation:fortified_glass@0"
            ]
        },
        {
            "x": 0,
            "y": 2,
            "z": 9,
            "elements": [
                "modularmachinery:blockcasing@4"
            ]
        },
        {
            "x": 0,
            "y": 0,
            "z": 8,
            "elements": [
                "contenttweaker:portion_of_the_sun@0"
            ]
        },
        {
            "x": 1,
            "y": 0,
            "z": 8,
            "elements": [
                "thaumicaugmentation:fortified_glass@0"
            ]
        },
        {
            "x": 2,
            "y": -1,
            "z": 0,
            "elements": [
                "modularmachinery:blockcasing@4"
            ]
        },
        {
            "x": 1,
            "y": -1,
            "z": 0,
            "elements": [
                "modularmachinery:blockcasing@4"
            ]
        },
        {
            "x": 0,
            "y": -1,
            "z": 0,
            "elements": [
                "modularmachinery:blockcasing@4"
            ]
        },
        {
            "x": -1,
            "y": 1,
            "z": 0,
            "elements": [
                "modularmachinery:blockcasing@4"
            ]
        },
        {
            "x": -1,
            "y": -1,
            "z": 0,
            "elements": [
                "modularmachinery:blockcasing@4"
            ]
        },
        {
            "x": 0,
            "y": 1,
            "z": 0,
            "elements": [
                "modularmachinery:blockcasing@4"
            ]
        },
        {
            "x": -2,
            "y": -1,
            "z": 0,
            "elements": [
                "modularmachinery:blockcasing@4"
            ]
        },
        {
            "x": 1,
            "y": 1,
            "z": 0,
            "elements": [
                "modularmachinery:blockcasing@4"
            ]
        },
        {
            "x": 0,
            "y": 5,
            "z": 6,
            "elements": [
                "modularmachinery:blockcasing@4"
            ]
        },
        {
            "x": -2,
            "y": -1,
            "z": 3,
            "elements": [
                "modularmachinery:blockcasing@4"
            ]
        },
        {
            "x": -1,
            "y": -1,
            "z": 3,
            "elements": [
                "modularmachinery:blockcasing@2"
            ]
        },
        {
            "x": 0,
            "y": -1,
            "z": 3,
            "elements": [
                "contenttweaker:hyperglued_meteoric_casing@0"
            ]
        },
        {
            "x": 1,
            "y": -1,
            "z": 3,
            "elements": [
                "modularmachinery:blockcasing@2"
            ]
        },
        {
            "x": 2,
            "y": -1,
            "z": 3,
            "elements": [
                "modularmachinery:blockcasing@4"
            ]
        },
        {
            "x": -1,
            "y": 1,
            "z": 8,
            "elements": [
                "thaumicaugmentation:fortified_glass@0"
            ]
        },
        {
            "x": -1,
            "y": -1,
            "z": 7,
            "elements": [
                "modularmachinery:blockcasing@4"
            ]
        },
        {
            "x": 0,
            "y": 1,
            "z": 8,
            "elements": [
                "contenttweaker:portion_of_the_sun@0"
            ]
        },
        {
            "x": 0,
            "y": -1,
            "z": 7,
            "elements": [
                "modularmachinery:blockcasing@4"
            ]
        },
        {
            "x": 1,
            "y": 1,
            "z": 8,
            "elements": [
                "thaumicaugmentation:fortified_glass@0"
            ]
        },
        {
            "x": 1,
            "y": -1,
            "z": 7,
            "elements": [
                "modularmachinery:blockcasing@4"
            ]
        },
        {
            "x": 0,
            "y": 4,
            "z": 5,
            "elements": [
                "modularmachinery:blockcasing@4"
            ]
        },
        {
            "x": -1,
            "y": 2,
            "z": 8,
            "elements": [
                "modularmachinery:blockcasing@4"
            ]
        },
        {
            "x": -1,
            "y": 0,
            "z": 7,
            "elements": [
                "modularmachinery:blockcasing@4"
            ]
        },
        {
            "x": 0,
            "y": 2,
            "z": 8,
            "elements": [
                "contenttweaker:portion_of_the_sun@0"
            ]
        },
        {
            "x": 0,
            "y": 0,
            "z": 7,
            "elements": [
                "modularmachinery:blockcasing@4"
            ]
        },
        {
            "x": 1,
            "y": 2,
            "z": 8,
            "elements": [
                "modularmachinery:blockcasing@4"
            ]
        },
        {
            "x": 1,
            "y": 0,
            "z": 7,
            "elements": [
                "modularmachinery:blockcasing@4"
            ]
        },
        {
            "x": -1,
            "y": 5,
            "z": 5,
            "elements": [
                "modularmachinery:blockcasing@4"
            ]
        },
        {
            "x": 0,
            "y": 5,
            "z": 5,
            "elements": [
                "contenttweaker:portion_of_the_sun@0"
            ]
        },
        {
            "x": -2,
            "y": -1,
            "z": 2,
            "elements": [
                "modularmachinery:blockcasing@4"
            ]
        },
        {
            "x": 1,
            "y": 5,
            "z": 5,
            "elements": [
                "modularmachinery:blockcasing@4"
            ]
        },
        {
            "x": 0,
            "y": 3,
            "z": 4,
            "elements": [
                "thaumicaugmentation:bars@0"
            ]
        },
        {
            "x": -1,
            "y": -1,
            "z": 2,
            "elements": [
                "modularmachinery:blockcasing@2"
            ]
        },
        {
            "x": 0,
            "y": 1,
            "z": 3,
            "elements": [
                "mekanism:machineblock2@13"
            ]
        },
        {
            "x": 0,
            "y": -1,
            "z": 2,
            "elements": [
                "modularmachinery:blockcasing@2"
            ]
        },
        {
            "x": 1,
            "y": -1,
            "z": 2,
            "elements": [
                "modularmachinery:blockcasing@2"
            ]
        },
        {
            "x": 2,
            "y": -1,
            "z": 2,
            "elements": [
                "modularmachinery:blockcasing@4"
            ]
        },
        {
            "x": -1,
            "y": 1,
            "z": 7,
            "elements": [
                "modularmachinery:blockcasing@4"
            ]
        },
        {
            "x": 0,
            "y": 3,
            "z": 8,
            "elements": [
                "modularmachinery:blockcasing@4"
            ]
        },
        {
            "x": -1,
            "y": -1,
            "z": 6,
            "elements": [
                "modularmachinery:blockcasing@4"
            ]
        },
        {
            "x": 0,
            "y": 1,
            "z": 7,
            "elements": [
                "modularmachinery:blockcasing@4"
            ]
        },
        {
            "x": 0,
            "y": -1,
            "z": 6,
            "elements": [
                "modularmachinery:blockcasing@4"
            ]
        },
        {
            "x": 1,
            "y": 1,
            "z": 7,
            "elements": [
                "modularmachinery:blockcasing@4"
            ]
        },
        {
            "x": 1,
            "y": -1,
            "z": 6,
            "elements": [
                "modularmachinery:blockcasing@4"
            ]
        },
        {
            "x": 0,
            "y": 6,
            "z": 5,
            "elements": [
                "modularmachinery:blockcasing@4"
            ]
        },
        {
            "x": 0,
            "y": 4,
            "z": 4,
            "elements": [
                "modularmachinery:blockcasing@4"
            ]
        },
        {
            "x": 0,
            "y": 2,
            "z": 3,
            "elements": [
                "modularmachinery:blockcasing@4"
            ]
        },
        {
            "x": -1,
            "y": 2,
            "z": 7,
            "elements": [
                "modularmachinery:blockcasing@4"
            ]
        },
        {
            "x": 0,
            "y": 2,
            "z": 7,
            "elements": [
                "modularmachinery:blockcasing@4"
            ]
        },
        {
            "x": 1,
            "y": 2,
            "z": 7,
            "elements": [
                "modularmachinery:blockcasing@4"
            ]
        },
        {
            "x": -1,
            "y": 5,
            "z": 4,
            "elements": [
                "modularmachinery:blockcasing@4"
            ]
        },
        {
            "x": 0,
            "y": 5,
            "z": 4,
            "elements": [
                "contenttweaker:portion_of_the_sun@0"
            ]
        },
        {
            "x": -1,
            "y": 3,
            "z": 3,
            "elements": [
                "thaumicaugmentation:bars@0"
            ]
        },
        {
            "x": -2,
            "y": -1,
            "z": 1,
            "elements": [
                "modularmachinery:blockcasing@4"
            ]
        },
        {
            "x": 1,
            "y": 5,
            "z": 4,
            "elements": [
                "modularmachinery:blockcasing@4"
            ]
        },
        {
            "x": 0,
            "y": 3,
            "z": 3,
            "elements": [
                "modularmachinery:blockcasing@4"
            ]
        },
        {
            "x": -1,
            "y": -1,
            "z": 1,
            "elements": [
                "modularmachinery:blockcasing@4"
            ]
        },
        {
            "x": 1,
            "y": 3,
            "z": 3,
            "elements": [
                "thaumicaugmentation:bars@0"
            ]
        },
        {
            "x": 0,
            "y": -1,
            "z": 1,
            "elements": [
                "modularmachinery:blockcasing@4"
            ]
        },
        {
            "x": 1,
            "y": -1,
            "z": 1,
            "elements": [
                "modularmachinery:blockcasing@4"
            ]
        },
        {
            "x": -1,
            "y": 3,
            "z": 7,
            "elements": [
                "modularmachinery:blockcasing@4"
            ]
        },
        {
            "x": 2,
            "y": -1,
            "z": 1,
            "elements": [
                "modularmachinery:blockcasing@4"
            ]
        },
        {
            "x": -2,
            "y": -1,
            "z": 5,
            "elements": [
                "modularmachinery:blockcasing@4"
            ]
        },
        {
            "x": 0,
            "y": 3,
            "z": 7,
            "elements": [
                "contenttweaker:portion_of_the_sun@0"
            ]
        },
        {
            "x": -1,
            "y": -1,
            "z": 5,
            "elements": [
                "modularmachinery:blockcasing@4"
            ]
        },
        {
            "x": 1,
            "y": 3,
            "z": 7,
            "elements": [
                "modularmachinery:blockcasing@4"
            ]
        },
        {
            "x": 0,
            "y": -1,
            "z": 5,
            "elements": [
                "modularmachinery:blockcasing@4"
            ]
        },
        {
            "x": 1,
            "y": -1,
            "z": 5,
            "elements": [
                "modularmachinery:blockcasing@4"
            ]
        },
        {
            "x": 2,
            "y": -1,
            "z": 5,
            "elements": [
                "modularmachinery:blockcasing@4"
            ]
        },
        {
            "x": -1,
            "y": -1,
            "z": 9,
            "elements": [
                "modularmachinery:blockcasing@4"
            ]
        },
        {
            "x": 0,
            "y": -1,
            "z": 9,
            "elements": [
                "modularmachinery:blockcasing@4"
            ]
        },
        {
            "x": 1,
            "y": -1,
            "z": 9,
            "elements": [
                "modularmachinery:blockcasing@4"
            ]
        },
        {
            "x": 0,
            "y": 6,
            "z": 4,
            "elements": [
                "modularmachinery:blockcasing@4"
            ]
        },
        {
            "x": -1,
            "y": 4,
            "z": 3,
            "elements": [
                "modularmachinery:blockcasing@4"
            ]
        },
        {
            "x": 0,
            "y": 4,
            "z": 3,
            "elements": [
                "contenttweaker:portion_of_the_sun@0"
            ]
        },
        {
            "x": 1,
            "y": 4,
            "z": 3,
            "elements": [
                "modularmachinery:blockcasing@4"
            ]
        },
        {
            "x": 0,
            "y": 4,
            "z": 7,
            "elements": [
                "modularmachinery:blockcasing@4"
            ]
        },
        {
            "x": -1,
            "y": 0,
            "z": 9,
            "elements": [
                "modularmachinery:blockcasing@4"
            ]
        },
        {
            "x": 0,
            "y": 0,
            "z": 9,
            "elements": [
                "modularmachinery:blockenergyinputhatch@5",
                "modularmachinery:blockenergyinputhatch@6",
                "modularmachinery:blockenergyinputhatch@7"
            ]
        },
        {
            "x": 1,
            "y": 0,
            "z": 9,
            "elements": [
                "modularmachinery:blockcasing@4"
            ]
        },
        {
            "x": 0,
            "y": 5,
            "z": 3,
            "elements": [
                "modularmachinery:blockcasing@4"
            ]
        },
        {
            "x": 0,
            "y": 3,
            "z": 2,
            "elements": [
                "thaumicaugmentation:bars@0"
            ]
        },
        {
            "x": -2,
            "y": -1,
            "z": 4,
            "elements": [
                "modularmachinery:blockcasing@4"
            ]
        },
        {
            "x": 0,
            "y": 3,
            "z": 6,
            "elements": [
                "modularmachinery:blockcasing@4"
            ]
        },
        {
            "x": -1,
            "y": -1,
            "z": 4,
            "elements": [
                "modularmachinery:blockcasing@2"
            ]
        },
        {
            "x": 0,
            "y": -1,
            "z": 4,
            "elements": [
                "modularmachinery:blockcasing@2"
            ]
        },
        {
            "x": 1,
            "y": -1,
            "z": 4,
            "elements": [
                "modularmachinery:blockcasing@2"
            ]
        },
        {
            "x": 2,
            "y": -1,
            "z": 4,
            "elements": [
                "modularmachinery:blockcasing@4"
            ]
        },
        {
            "x": -1,
            "y": 1,
            "z": 9,
            "elements": [
                "modularmachinery:blockcasing@4"
            ]
        },
        {
            "x": -1,
            "y": -1,
            "z": 8,
            "elements": [
                "modularmachinery:blockcasing@4"
            ]
        },
        {
            "x": 0,
            "y": 1,
            "z": 9,
            "elements": [
                "modularmachinery:blockcasing@4"
            ]
        },
        {
            "x": 0,
            "y": -1,
            "z": 8,
            "elements": [
                "modularmachinery:blockcasing@4"
            ]
        },
        {
            "x": 1,
            "y": 1,
            "z": 9,
            "elements": [
                "modularmachinery:blockcasing@4"
            ]
        },
        {
            "x": 1,
            "y": -1,
            "z": 8,
            "elements": [
                "modularmachinery:blockcasing@4"
            ]
        },
        {
            "x": 0,
            "y": 4,
            "z": 2,
            "elements": [
                "modularmachinery:blockcasing@4"
            ]
        }
    ]}